<?xml version='1.0' encoding='UTF-8'?>
<mujoco model="ur3">
  <compiler angle="radian" meshdir="../meshes/ur3/collision/"/>

  <asset>
    <mesh name="base" file="base.stl"/>
    <mesh name="shoulder" file="shoulder.stl"/>
    <mesh name="upperarm" file="upperarm.stl"/>
    <mesh name="forearm" file="forearm.stl"/>
    <mesh name="wrist1" file="wrist1.stl"/>
    <mesh name="wrist2" file="wrist2.stl"/>
    <mesh name="wrist3" file="wrist3.stl"/>
  </asset>

  <worldbody>
    <body name="base_link">
      <inertial pos="0 0 0" quat="0.5 0.5 -0.5 0.5" mass="2" diaginertia="0.005625 0.00305317 0.00305317"/>
      <geom type="mesh" contype="0" conaffinity="0" group="1" density="0" rgba="0.7 0.7 0.7 1" mesh="base"/>
      <geom type="mesh" rgba="0.7 0.7 0.7 1" mesh="base"/>
      <body name="shoulder_link" pos="0 0 0.1519">
        <inertial pos="0 0 0" mass="4.1" diaginertia="0.00809316 0.00809316 0.0057505"/>
        <joint name="shoulder_pan_joint" pos="0 0 0" axis="0 0 1" range="-6.28319 6.28319" actuatorfrcrange="-330 330" armature="3.2530854999999996"/>
        <geom type="mesh" contype="0" conaffinity="0" group="1" density="0" rgba="0.7 0.7 0.7 1" mesh="shoulder"/>
        <geom type="mesh" rgba="0.7 0.7 0.7 1" mesh="shoulder"/>
        <body name="upper_arm_link" pos="0 0.1198 0" quat="0.707107 0 0.707107 0">
          <inertial pos="0 0 0.121825" mass="5.52" diaginertia="0.0217285 0.021854 0.00961875"/>
          <joint name="shoulder_lift_joint" pos="0 0 0" axis="0 1 0" range="-6.28319 6.28319" actuatorfrcrange="-330 330" armature="1.2802254999999998"/>
          <geom type="mesh" contype="0" conaffinity="0" group="1" density="0" rgba="0.7 0.7 0.7 1" mesh="upperarm"/>
          <geom type="mesh" rgba="0.7 0.7 0.7 1" mesh="upperarm"/>
          <body name="forearm_link" pos="0 -0.0925 0.24365">
            <inertial pos="0 0 0.106625" mass="3.3600000000000003" diaginertia="0.00654681 0.00667231 0.00354375"/>
            <joint name="elbow_joint" pos="0 0 0" axis="0 1 0" range="-3.14159 3.14159" actuatorfrcrange="-150 150" armature="0.8234054999999999"/>
            <geom type="mesh" contype="0" conaffinity="0" group="1" density="0" rgba="0.7 0.7 0.7 1" mesh="forearm"/>
            <geom type="mesh" rgba="0.7 0.7 0.7 1" mesh="forearm"/>
            <body name="wrist_1_link" pos="0 0 0.21325" quat="0.707107 0 0.707107 0">
              <inertial pos="0 0 0" quat="0.5 0.5 -0.5 0.5" mass="2.9000000000000004" diaginertia="0.00225 0.0022105 0.002085"/>
              <joint name="wrist_1_joint" pos="0 0 0" axis="0 1 0" range="-6.28319 6.28319" actuatorfrcrange="-54 54" armature="0.3264255"/>
              <geom type="mesh" contype="0" conaffinity="0" group="1" density="0" rgba="0.7 0.7 0.7 1" mesh="wrist1"/>
              <geom type="mesh" rgba="0.7 0.7 0.7 1" mesh="wrist1"/>
              <body name="wrist_2_link" pos="0 0.08505 0">
                <inertial pos="0 0 0" quat="0.5 0.5 -0.5 0.5" mass="2.9000000000000004" diaginertia="0.00225 0.002085 0.0022105"/>
                <joint name="wrist_2_joint" pos="0 0 0" axis="0 0 1" range="-6.28319 6.28319" actuatorfrcrange="-54 54" armature="0.3264255"/>
                <geom type="mesh" contype="0" conaffinity="0" group="1" density="0" rgba="0.7 0.7 0.7 1" mesh="wrist2"/>
                <geom type="mesh" rgba="0.7 0.7 0.7 1" mesh="wrist2"/>
                <body name="wrist_3_link" pos="0 0 0.08535">
                  <inertial pos="0 0 0" quat="0.5 0.5 -0.5 0.5" mass="2.45" diaginertia="0.000984375 0.00103769 0.000912187"/>
                  <joint name="wrist_3_joint" pos="0 0 0" axis="0 1 0" range="-6.28319 6.28319" actuatorfrcrange="-54 54" armature="0.3264255"/>
                  <geom type="mesh" contype="0" conaffinity="0" group="1" density="0" rgba="0.7 0.7 0.7 1" mesh="wrist3"/>
                  <geom type="mesh" rgba="0.7 0.7 0.7 1" mesh="wrist3"/>
                  <body name="ee_link" pos="0 0.0819 0" quat="0.707107 0 0 0.707107">
                    <geom size="0.005 0.005 0.005" pos="-0.01 0 0" type="box"/>
                  </body>
                  <body name="tool0" pos="0 0.0819 0" quat="0.707107 -0.707107 0 0"/>
                </body>
              </body>
            </body>
          </body>
        </body>
      </body>
      <body name="base" quat="0 0 0 -1"/>
    </body>
  </worldbody>
<actuator><motor name="CRA-RI80-110-PRO-XX.161_shoulder_pan_joint" joint="shoulder_pan_joint" ctrlrange="0 133"/><motor name="CRA-RI80-110-PRO-XX.101_shoulder_lift_joint" joint="shoulder_lift_joint" ctrlrange="0 133"/><motor name="CRA-RI80-110-PRO-XX.81_elbow_joint" joint="elbow_joint" ctrlrange="0 107"/><motor name="CRA-RI80-110-PRO-XX.51_wrist_1_joint" joint="wrist_1_joint" ctrlrange="0 68.5"/><motor name="CRA-RI80-110-PRO-XX.51_wrist_2_joint" joint="wrist_2_joint" ctrlrange="0 68.5"/><motor name="CRA-RI80-110-PRO-XX.51_wrist_3_joint" joint="wrist_3_joint" ctrlrange="0 68.5"/></actuator></mujoco>
